Workbook

Sheet Charts
A1: Charts — copy any of these straight into PowerPoint
A2: Right-click → Copy, paste into a slide. They stay linked to this workbook, so changing an assumption updates the slide. Data is on the Model and Sensitivity sheets.
A4: Two more charts live on the 'Pricing options' sheet, next to the tier table they respond to.

Sheet Assumptions
A1: Fluorsight — business model assumptions
A2: Change any yellow cell. Everything else in this workbook is a formula and will follow.
A5: Input | B5: Value | C5: Unit | D5: Status | E5: Where it comes from
A6: Portfolio size | B6: 500 | C6: samples / year | D6: MODELLED | E6: Illustrative annual programme for one customer. Our choice.
A7: Escalation rate | B7: 0.2 | C7: share screened | D7: MODELLED | E7: The weakest assumption in the model. See Sensitivity table A.
A8: Lab cost per sample | B8: 250 | C8: £ / sample | D8: MODELLED | E8: No UK lab publishes a rate card — 7 providers' published pricing checked, all quote on request.
A9: Annual subscription | B9: 5000 | C9: £ / year | D9: MODELLED | E9: Pricing decision. Set to 0 to model pure device-and-refills — see Sensitivity table D.
A10: Refill price to customer | B10: 40 | C10: £ / sample | D10: MODELLED | E10: What we charge per screen. A price, not a cost.
A11: Refill cost to us | B11: 1 | C11: £ / sample | D11: MODELLED | E11: Dom & Evan build costing, Sept 2026. Rounded up — their estimate was nearer 50p.
A12: Device cost to us | B12: 40 | C12: £ / device | D12: MODELLED | E12: Dom & Evan build costing, Sept 2026.
A13: Device price to customer | B13: 150 | C13: £ / device | D13: ASSUMED | E13: PLACEHOLDER — no pricing decision has been made. Change this.
A14: Devices per customer | B14: 1 | C14: devices | D14: ASSUMED | E14: PLACEHOLDER — one reader per customer. A field team may need several.
A16: Reference — context, not inputs
A17: Lab turnaround | B17: 10–15 working days | D17: PUBLISHED | E17: SOCOTEC UK PFAS page, checked Sept 2026.
A18: Published water price (Finland) | B18: €175–300 / sample | D18: PUBLISHED | E18: Measurlabs list price. Not UK, not like-for-like scope.
A19: Nearest published UK figure | B19: £350 / sample | D19: PUBLISHED | E19: EIA to Commons EAC, May 2025 — SOIL, explicitly excludes water. Does NOT validate the £250.

Sheet Model
A1: The model — one customer, one year
A2: Every cell is a formula off the Assumptions sheet.
A5: What the customer pays
A6: Testing everything at the lab | B6: =Assumptions!B6*Assumptions!B8 | C6: The do-nothing baseline: portfolio × lab cost.
A7: Samples escalated to the lab | B7: =ROUND(Assumptions!B6*Assumptions!B7,0)
A8: Lab spend under triage | B8: =B7*Assumptions!B8
A9: Screening refills | B9: =Assumptions!B6*Assumptions!B10 | C9: Every sample is screened, so this is the whole portfolio.
A10: Software subscription | B10: =Assumptions!B9
A11: Devices | B11: =Assumptions!B13*Assumptions!B14 | C11: One-off. A durable reader, not a per-year cost.
A12: Total with Fluorsight | B12: =B8+B9+B10+B11
A13: Customer saving | B13: =B6-B12
A14: Saving as a share | B14: =B13/B6
A16: What it means for us
A17: Revenue | B17: =Assumptions!B9+Assumptions!B6*Assumptions!B10+Assumptions!B13*Assumptions!B14 | C17: Subscription + refills + device sale.
A18: Cost of goods | B18: =Assumptions!B6*Assumptions!B11+Assumptions!B14*Assumptions!B12 | C18: Refills + devices, at our cost.
A19: Gross profit | B19: =B17-B18
A20: Gross margin | B20: =B19/B17
A21: margin on the device alone | B21: =Assumptions!B14*(Assumptions!B13-Assumptions!B12)
A22: device as a share of revenue | B22: =Assumptions!B13*Assumptions!B14/B17 | C22: If this reads ~1%, the razor-and-blades story is about the refills, not the razor.
A24: The robustness test
A25: Break-even lab cost | B25: =(Assumptions!B6*Assumptions!B10+Assumptions!B9+Assumptions!B13*Assumptions!B14)/(Assumptions!B6*(1-Assumptions!B7)) | C25: Triage stops paying only if lab analysis falls below this. We assume £250, so the conclusion survives being badly wrong.
A28: Chart data — cost comparison
B29: Lab analysis | C29: Refills | D29: Subscription | E29: Devices
A30: Test everything | B30: =B6 | C30: 0 | D30: 0 | E30: 0
A31: With Fluorsight | B31: =B8 | C31: =B9 | D31: =B10 | E31: =B11

Sheet Sensitivity
A1: Sensitivity — what happens when the assumptions are wrong
A2: All live off the Assumptions sheet. These four tables feed the charts.
L3: The subscription is fixed, so it swamps a small programme. Set the subscription to 0 and watch the blue line flatten onto the orange one.
A4: A · If more samples escalate than we assume | E4: B · Break-even — how cheap would the lab have to get? | H4: C · What we charge per refill | L4: D · Does the saving hold for a SMALL customer?
A5: Escalation rate | B5: Customer saving (£) | C5: Saving (%) | E5: Lab cost (£/sample) | F5: Net saving (£) | H5: Refill price (£) | I5: Customer saving (£) | J5: Our revenue (£) | L5: Samples / year | M5: Saving with subscription | N5: Saving, refills only
A6: 0.05 | B6: =Model!$B$6-(ROUND(Assumptions!$B$6*A6,0)*Assumptions!$B$8+Model!$B$9+Model!$B$10+Model!$B$11) | C6: =B6/Model!$B$6 | E6: 25 | F6: =Assumptions!$B$6*E6-(ROUND(Assumptions!$B$6*Assumptions!$B$7,0)*E6+Model!$B$9+Model!$B$10+Model!$B$11) | H6: 1 | I6: =Model!$B$6-(Model!$B$8+Assumptions!$B$6*H6+Model!$B$10+Model!$B$11) | J6: =Assumptions!$B$9+Assumptions!$B$6*H6+Model!$B$11 | L6: 25 | M6: =(L6*Assumptions!$B$8-(ROUND(L6*Assumptions!$B$7,0)*Assumptions!$B$8+L6*Assumptions!$B$10+Assumptions!$B$9+Model!$B$11))/(L6*Assumptions!$B$8) | N6: =(L6*Assumptions!$B$8-(ROUND(L6*Assumptions!$B$7,0)*Assumptions!$B$8+L6*Assumptions!$B$10+Model!$B$11))/(L6*Assumptions!$B$8)
A7: 0.1 | B7: =Model!$B$6-(ROUND(Assumptions!$B$6*A7,0)*Assumptions!$B$8+Model!$B$9+Model!$B$10+Model!$B$11) | C7: =B7/Model!$B$6 | E7: 50 | F7: =Assumptions!$B$6*E7-(ROUND(Assumptions!$B$6*Assumptions!$B$7,0)*E7+Model!$B$9+Model!$B$10+Model!$B$11) | H7: 2 | I7: =Model!$B$6-(Model!$B$8+Assumptions!$B$6*H7+Model!$B$10+Model!$B$11) | J7: =Assumptions!$B$9+Assumptions!$B$6*H7+Model!$B$11 | L7: 50 | M7: =(L7*Assumptions!$B$8-(ROUND(L7*Assumptions!$B$7,0)*Assumptions!$B$8+L7*Assumptions!$B$10+Assumptions!$B$9+Model!$B$11))/(L7*Assumptions!$B$8) | N7: =(L7*Assumptions!$B$8-(ROUND(L7*Assumptions!$B$7,0)*Assumptions!$B$8+L7*Assumptions!$B$10+Model!$B$11))/(L7*Assumptions!$B$8)
A8: 0.15 | B8: =Model!$B$6-(ROUND(Assumptions!$B$6*A8,0)*Assumptions!$B$8+Model!$B$9+Model!$B$10+Model!$B$11) | C8: =B8/Model!$B$6 | E8: 75 | F8: =Assumptions!$B$6*E8-(ROUND(Assumptions!$B$6*Assumptions!$B$7,0)*E8+Model!$B$9+Model!$B$10+Model!$B$11) | H8: 5 | I8: =Model!$B$6-(Model!$B$8+Assumptions!$B$6*H8+Model!$B$10+Model!$B$11) | J8: =Assumptions!$B$9+Assumptions!$B$6*H8+Model!$B$11 | L8: 100 | M8: =(L8*Assumptions!$B$8-(ROUND(L8*Assumptions!$B$7,0)*Assumptions!$B$8+L8*Assumptions!$B$10+Assumptions!$B$9+Model!$B$11))/(L8*Assumptions!$B$8) | N8: =(L8*Assumptions!$B$8-(ROUND(L8*Assumptions!$B$7,0)*Assumptions!$B$8+L8*Assumptions!$B$10+Model!$B$11))/(L8*Assumptions!$B$8)
A9: 0.2 | B9: =Model!$B$6-(ROUND(Assumptions!$B$6*A9,0)*Assumptions!$B$8+Model!$B$9+Model!$B$10+Model!$B$11) | C9: =B9/Model!$B$6 | E9: 100 | F9: =Assumptions!$B$6*E9-(ROUND(Assumptions!$B$6*Assumptions!$B$7,0)*E9+Model!$B$9+Model!$B$10+Model!$B$11) | H9: 10 | I9: =Model!$B$6-(Model!$B$8+Assumptions!$B$6*H9+Model!$B$10+Model!$B$11) | J9: =Assumptions!$B$9+Assumptions!$B$6*H9+Model!$B$11 | L9: 200 | M9: =(L9*Assumptions!$B$8-(ROUND(L9*Assumptions!$B$7,0)*Assumptions!$B$8+L9*Assumptions!$B$10+Assumptions!$B$9+Model!$B$11))/(L9*Assumptions!$B$8) | N9: =(L9*Assumptions!$B$8-(ROUND(L9*Assumptions!$B$7,0)*Assumptions!$B$8+L9*Assumptions!$B$10+Model!$B$11))/(L9*Assumptions!$B$8)
A10: 0.25 | B10: =Model!$B$6-(ROUND(Assumptions!$B$6*A10,0)*Assumptions!$B$8+Model!$B$9+Model!$B$10+Model!$B$11) | C10: =B10/Model!$B$6 | E10: 125 | F10: =Assumptions!$B$6*E10-(ROUND(Assumptions!$B$6*Assumptions!$B$7,0)*E10+Model!$B$9+Model!$B$10+Model!$B$11) | H10: 15 | I10: =Model!$B$6-(Model!$B$8+Assumptions!$B$6*H10+Model!$B$10+Model!$B$11) | J10: =Assumptions!$B$9+Assumptions!$B$6*H10+Model!$B$11 | L10: 300 | M10: =(L10*Assumptions!$B$8-(ROUND(L10*Assumptions!$B$7,0)*Assumptions!$B$8+L10*Assumptions!$B$10+Assumptions!$B$9+Model!$B$11))/(L10*Assumptions!$B$8) | N10: =(L10*Assumptions!$B$8-(ROUND(L10*Assumptions!$B$7,0)*Assumptions!$B$8+L10*Assumptions!$B$10+Model!$B$11))/(L10*Assumptions!$B$8)
A11: 0.3 | B11: =Model!$B$6-(ROUND(Assumptions!$B$6*A11,0)*Assumptions!$B$8+Model!$B$9+Model!$B$10+Model!$B$11) | C11: =B11/Model!$B$6 | E11: 150 | F11: =Assumptions!$B$6*E11-(ROUND(Assumptions!$B$6*Assumptions!$B$7,0)*E11+Model!$B$9+Model!$B$10+Model!$B$11) | H11: 20 | I11: =Model!$B$6-(Model!$B$8+Assumptions!$B$6*H11+Model!$B$10+Model!$B$11) | J11: =Assumptions!$B$9+Assumptions!$B$6*H11+Model!$B$11 | L11: 500 | M11: =(L11*Assumptions!$B$8-(ROUND(L11*Assumptions!$B$7,0)*Assumptions!$B$8+L11*Assumptions!$B$10+Assumptions!$B$9+Model!$B$11))/(L11*Assumptions!$B$8) | N11: =(L11*Assumptions!$B$8-(ROUND(L11*Assumptions!$B$7,0)*Assumptions!$B$8+L11*Assumptions!$B$10+Model!$B$11))/(L11*Assumptions!$B$8)
A12: 0.35 | B12: =Model!$B$6-(ROUND(Assumptions!$B$6*A12,0)*Assumptions!$B$8+Model!$B$9+Model!$B$10+Model!$B$11) | C12: =B12/Model!$B$6 | E12: 175 | F12: =Assumptions!$B$6*E12-(ROUND(Assumptions!$B$6*Assumptions!$B$7,0)*E12+Model!$B$9+Model!$B$10+Model!$B$11) | H12: 25 | I12: =Model!$B$6-(Model!$B$8+Assumptions!$B$6*H12+Model!$B$10+Model!$B$11) | J12: =Assumptions!$B$9+Assumptions!$B$6*H12+Model!$B$11 | L12: 750 | M12: =(L12*Assumptions!$B$8-(ROUND(L12*Assumptions!$B$7,0)*Assumptions!$B$8+L12*Assumptions!$B$10+Assumptions!$B$9+Model!$B$11))/(L12*Assumptions!$B$8) | N12: =(L12*Assumptions!$B$8-(ROUND(L12*Assumptions!$B$7,0)*Assumptions!$B$8+L12*Assumptions!$B$10+Model!$B$11))/(L12*Assumptions!$B$8)
A13: 0.4 | B13: =Model!$B$6-(ROUND(Assumptions!$B$6*A13,0)*Assumptions!$B$8+Model!$B$9+Model!$B$10+Model!$B$11) | C13: =B13/Model!$B$6 | E13: 200 | F13: =Assumptions!$B$6*E13-(ROUND(Assumptions!$B$6*Assumptions!$B$7,0)*E13+Model!$B$9+Model!$B$10+Model!$B$11) | H13: 30 | I13: =Model!$B$6-(Model!$B$8+Assumptions!$B$6*H13+Model!$B$10+Model!$B$11) | J13: =Assumptions!$B$9+Assumptions!$B$6*H13+Model!$B$11 | L13: 1000 | M13: =(L13*Assumptions!$B$8-(ROUND(L13*Assumptions!$B$7,0)*Assumptions!$B$8+L13*Assumptions!$B$10+Assumptions!$B$9+Model!$B$11))/(L13*Assumptions!$B$8) | N13: =(L13*Assumptions!$B$8-(ROUND(L13*Assumptions!$B$7,0)*Assumptions!$B$8+L13*Assumptions!$B$10+Model!$B$11))/(L13*Assumptions!$B$8)
A14: 0.45 | B14: =Model!$B$6-(ROUND(Assumptions!$B$6*A14,0)*Assumptions!$B$8+Model!$B$9+Model!$B$10+Model!$B$11) | C14: =B14/Model!$B$6 | E14: 225 | F14: =Assumptions!$B$6*E14-(ROUND(Assumptions!$B$6*Assumptions!$B$7,0)*E14+Model!$B$9+Model!$B$10+Model!$B$11) | H14: 35 | I14: =Model!$B$6-(Model!$B$8+Assumptions!$B$6*H14+Model!$B$10+Model!$B$11) | J14: =Assumptions!$B$9+Assumptions!$B$6*H14+Model!$B$11
A15: 0.5 | B15: =Model!$B$6-(ROUND(Assumptions!$B$6*A15,0)*Assumptions!$B$8+Model!$B$9+Model!$B$10+Model!$B$11) | C15: =B15/Model!$B$6 | E15: 250 | F15: =Assumptions!$B$6*E15-(ROUND(Assumptions!$B$6*Assumptions!$B$7,0)*E15+Model!$B$9+Model!$B$10+Model!$B$11) | H15: 40 | I15: =Model!$B$6-(Model!$B$8+Assumptions!$B$6*H15+Model!$B$10+Model!$B$11) | J15: =Assumptions!$B$9+Assumptions!$B$6*H15+Model!$B$11
A16: 0.55 | B16: =Model!$B$6-(ROUND(Assumptions!$B$6*A16,0)*Assumptions!$B$8+Model!$B$9+Model!$B$10+Model!$B$11) | C16: =B16/Model!$B$6 | E16: 275 | F16: =Assumptions!$B$6*E16-(ROUND(Assumptions!$B$6*Assumptions!$B$7,0)*E16+Model!$B$9+Model!$B$10+Model!$B$11) | H16: 50 | I16: =Model!$B$6-(Model!$B$8+Assumptions!$B$6*H16+Model!$B$10+Model!$B$11) | J16: =Assumptions!$B$9+Assumptions!$B$6*H16+Model!$B$11
E17: 300 | F17: =Assumptions!$B$6*E17-(ROUND(Assumptions!$B$6*Assumptions!$B$7,0)*E17+Model!$B$9+Model!$B$10+Model!$B$11)
E18: 325 | F18: =Assumptions!$B$6*E18-(ROUND(Assumptions!$B$6*Assumptions!$B$7,0)*E18+Model!$B$9+Model!$B$10+Model!$B$11)
E19: 350 | F19: =Assumptions!$B$6*E19-(ROUND(Assumptions!$B$6*Assumptions!$B$7,0)*E19+Model!$B$9+Model!$B$10+Model!$B$11)
E20: 375 | F20: =Assumptions!$B$6*E20-(ROUND(Assumptions!$B$6*Assumptions!$B$7,0)*E20+Model!$B$9+Model!$B$10+Model!$B$11)
E21: 400 | F21: =Assumptions!$B$6*E21-(ROUND(Assumptions!$B$6*Assumptions!$B$7,0)*E21+Model!$B$9+Model!$B$10+Model!$B$11)

Sheet Pricing options
A1: Pricing structures — what each one does to a small customer
A2: A fixed annual fee spread over few screens is what breaks the small end. Edit the yellow cells and watch the tables and both charts move.
A4: Structure | B4: Parameter | C4: Value
A5: A · Today | B5: Fixed annual fee | C5: 5000
B6: Price per screen | C6: 40
A7: B · Flat per-screen | B7: Price per screen | C7: 50
A8: C · Small base + per-screen | B8: Base annual fee | C8: 500
B9: Price per screen | C9: 45
A11: D · Tiers — a tier's price applies from its included volume; anything above is charged as overage
A12: Tier | B12: Screens included | C12: Annual price
A13: Pay as you go | B13: 0 | C13: 0
A14: Starter | B14: 25 | C14: 1250
A15: Small | B15: 50 | C15: 2500
A16: Standard | B16: 100 | C16: 5000
A17: Programme | B17: 200 | C17: 10000
A18: Enterprise | B18: 500 | C18: 25000
A19: Overage, per screen above the tier | C19: 50
A22: 1 · What the customer pays us (including the device)
A23: Samples / year | B23: A · Today | C23: B · Flat per-screen | D23: C · Base + per-screen | E23: D · Tiers
A24: 25 | B24: =$C$5+$C$6*$A24+Assumptions!$B$13*Assumptions!$B$14 | C24: =$C$7*$A24+Assumptions!$B$13*Assumptions!$B$14 | D24: =$C$8+$C$9*$A24+Assumptions!$B$13*Assumptions!$B$14 | E24: =INDEX($C$13:$C$18,MATCH($A24,$B$13:$B$18,1))+MAX(0,$A24-INDEX($B$13:$B$18,MATCH($A24,$B$13:$B$18,1)))*$C$19+Assumptions!$B$13*Assumptions!$B$14
A25: 50 | B25: =$C$5+$C$6*$A25+Assumptions!$B$13*Assumptions!$B$14 | C25: =$C$7*$A25+Assumptions!$B$13*Assumptions!$B$14 | D25: =$C$8+$C$9*$A25+Assumptions!$B$13*Assumptions!$B$14 | E25: =INDEX($C$13:$C$18,MATCH($A25,$B$13:$B$18,1))+MAX(0,$A25-INDEX($B$13:$B$18,MATCH($A25,$B$13:$B$18,1)))*$C$19+Assumptions!$B$13*Assumptions!$B$14
A26: 100 | B26: =$C$5+$C$6*$A26+Assumptions!$B$13*Assumptions!$B$14 | C26: =$C$7*$A26+Assumptions!$B$13*Assumptions!$B$14 | D26: =$C$8+$C$9*$A26+Assumptions!$B$13*Assumptions!$B$14 | E26: =INDEX($C$13:$C$18,MATCH($A26,$B$13:$B$18,1))+MAX(0,$A26-INDEX($B$13:$B$18,MATCH($A26,$B$13:$B$18,1)))*$C$19+Assumptions!$B$13*Assumptions!$B$14
A27: 150 | B27: =$C$5+$C$6*$A27+Assumptions!$B$13*Assumptions!$B$14 | C27: =$C$7*$A27+Assumptions!$B$13*Assumptions!$B$14 | D27: =$C$8+$C$9*$A27+Assumptions!$B$13*Assumptions!$B$14 | E27: =INDEX($C$13:$C$18,MATCH($A27,$B$13:$B$18,1))+MAX(0,$A27-INDEX($B$13:$B$18,MATCH($A27,$B$13:$B$18,1)))*$C$19+Assumptions!$B$13*Assumptions!$B$14
A28: 200 | B28: =$C$5+$C$6*$A28+Assumptions!$B$13*Assumptions!$B$14 | C28: =$C$7*$A28+Assumptions!$B$13*Assumptions!$B$14 | D28: =$C$8+$C$9*$A28+Assumptions!$B$13*Assumptions!$B$14 | E28: =INDEX($C$13:$C$18,MATCH($A28,$B$13:$B$18,1))+MAX(0,$A28-INDEX($B$13:$B$18,MATCH($A28,$B$13:$B$18,1)))*$C$19+Assumptions!$B$13*Assumptions!$B$14
A29: 300 | B29: =$C$5+$C$6*$A29+Assumptions!$B$13*Assumptions!$B$14 | C29: =$C$7*$A29+Assumptions!$B$13*Assumptions!$B$14 | D29: =$C$8+$C$9*$A29+Assumptions!$B$13*Assumptions!$B$14 | E29: =INDEX($C$13:$C$18,MATCH($A29,$B$13:$B$18,1))+MAX(0,$A29-INDEX($B$13:$B$18,MATCH($A29,$B$13:$B$18,1)))*$C$19+Assumptions!$B$13*Assumptions!$B$14
A30: 500 | B30: =$C$5+$C$6*$A30+Assumptions!$B$13*Assumptions!$B$14 | C30: =$C$7*$A30+Assumptions!$B$13*Assumptions!$B$14 | D30: =$C$8+$C$9*$A30+Assumptions!$B$13*Assumptions!$B$14 | E30: =INDEX($C$13:$C$18,MATCH($A30,$B$13:$B$18,1))+MAX(0,$A30-INDEX($B$13:$B$18,MATCH($A30,$B$13:$B$18,1)))*$C$19+Assumptions!$B$13*Assumptions!$B$14
A31: 750 | B31: =$C$5+$C$6*$A31+Assumptions!$B$13*Assumptions!$B$14 | C31: =$C$7*$A31+Assumptions!$B$13*Assumptions!$B$14 | D31: =$C$8+$C$9*$A31+Assumptions!$B$13*Assumptions!$B$14 | E31: =INDEX($C$13:$C$18,MATCH($A31,$B$13:$B$18,1))+MAX(0,$A31-INDEX($B$13:$B$18,MATCH($A31,$B$13:$B$18,1)))*$C$19+Assumptions!$B$13*Assumptions!$B$14
A32: 1000 | B32: =$C$5+$C$6*$A32+Assumptions!$B$13*Assumptions!$B$14 | C32: =$C$7*$A32+Assumptions!$B$13*Assumptions!$B$14 | D32: =$C$8+$C$9*$A32+Assumptions!$B$13*Assumptions!$B$14 | E32: =INDEX($C$13:$C$18,MATCH($A32,$B$13:$B$18,1))+MAX(0,$A32-INDEX($B$13:$B$18,MATCH($A32,$B$13:$B$18,1)))*$C$19+Assumptions!$B$13*Assumptions!$B$14
A35: 2 · Customer saving against testing everything at the lab
A36: Samples / year | B36: A · Today | C36: B · Flat per-screen | D36: C · Base + per-screen | E36: D · Tiers
A37: 25 | B37: =($A37*Assumptions!$B$8-(ROUND($A37*Assumptions!$B$7,0)*Assumptions!$B$8+B24))/($A37*Assumptions!$B$8) | C37: =($A37*Assumptions!$B$8-(ROUND($A37*Assumptions!$B$7,0)*Assumptions!$B$8+C24))/($A37*Assumptions!$B$8) | D37: =($A37*Assumptions!$B$8-(ROUND($A37*Assumptions!$B$7,0)*Assumptions!$B$8+D24))/($A37*Assumptions!$B$8) | E37: =($A37*Assumptions!$B$8-(ROUND($A37*Assumptions!$B$7,0)*Assumptions!$B$8+E24))/($A37*Assumptions!$B$8)
A38: 50 | B38: =($A38*Assumptions!$B$8-(ROUND($A38*Assumptions!$B$7,0)*Assumptions!$B$8+B25))/($A38*Assumptions!$B$8) | C38: =($A38*Assumptions!$B$8-(ROUND($A38*Assumptions!$B$7,0)*Assumptions!$B$8+C25))/($A38*Assumptions!$B$8) | D38: =($A38*Assumptions!$B$8-(ROUND($A38*Assumptions!$B$7,0)*Assumptions!$B$8+D25))/($A38*Assumptions!$B$8) | E38: =($A38*Assumptions!$B$8-(ROUND($A38*Assumptions!$B$7,0)*Assumptions!$B$8+E25))/($A38*Assumptions!$B$8)
A39: 100 | B39: =($A39*Assumptions!$B$8-(ROUND($A39*Assumptions!$B$7,0)*Assumptions!$B$8+B26))/($A39*Assumptions!$B$8) | C39: =($A39*Assumptions!$B$8-(ROUND($A39*Assumptions!$B$7,0)*Assumptions!$B$8+C26))/($A39*Assumptions!$B$8) | D39: =($A39*Assumptions!$B$8-(ROUND($A39*Assumptions!$B$7,0)*Assumptions!$B$8+D26))/($A39*Assumptions!$B$8) | E39: =($A39*Assumptions!$B$8-(ROUND($A39*Assumptions!$B$7,0)*Assumptions!$B$8+E26))/($A39*Assumptions!$B$8)
A40: 150 | B40: =($A40*Assumptions!$B$8-(ROUND($A40*Assumptions!$B$7,0)*Assumptions!$B$8+B27))/($A40*Assumptions!$B$8) | C40: =($A40*Assumptions!$B$8-(ROUND($A40*Assumptions!$B$7,0)*Assumptions!$B$8+C27))/($A40*Assumptions!$B$8) | D40: =($A40*Assumptions!$B$8-(ROUND($A40*Assumptions!$B$7,0)*Assumptions!$B$8+D27))/($A40*Assumptions!$B$8) | E40: =($A40*Assumptions!$B$8-(ROUND($A40*Assumptions!$B$7,0)*Assumptions!$B$8+E27))/($A40*Assumptions!$B$8)
A41: 200 | B41: =($A41*Assumptions!$B$8-(ROUND($A41*Assumptions!$B$7,0)*Assumptions!$B$8+B28))/($A41*Assumptions!$B$8) | C41: =($A41*Assumptions!$B$8-(ROUND($A41*Assumptions!$B$7,0)*Assumptions!$B$8+C28))/($A41*Assumptions!$B$8) | D41: =($A41*Assumptions!$B$8-(ROUND($A41*Assumptions!$B$7,0)*Assumptions!$B$8+D28))/($A41*Assumptions!$B$8) | E41: =($A41*Assumptions!$B$8-(ROUND($A41*Assumptions!$B$7,0)*Assumptions!$B$8+E28))/($A41*Assumptions!$B$8)
A42: 300 | B42: =($A42*Assumptions!$B$8-(ROUND($A42*Assumptions!$B$7,0)*Assumptions!$B$8+B29))/($A42*Assumptions!$B$8) | C42: =($A42*Assumptions!$B$8-(ROUND($A42*Assumptions!$B$7,0)*Assumptions!$B$8+C29))/($A42*Assumptions!$B$8) | D42: =($A42*Assumptions!$B$8-(ROUND($A42*Assumptions!$B$7,0)*Assumptions!$B$8+D29))/($A42*Assumptions!$B$8) | E42: =($A42*Assumptions!$B$8-(ROUND($A42*Assumptions!$B$7,0)*Assumptions!$B$8+E29))/($A42*Assumptions!$B$8)
A43: 500 | B43: =($A43*Assumptions!$B$8-(ROUND($A43*Assumptions!$B$7,0)*Assumptions!$B$8+B30))/($A43*Assumptions!$B$8) | C43: =($A43*Assumptions!$B$8-(ROUND($A43*Assumptions!$B$7,0)*Assumptions!$B$8+C30))/($A43*Assumptions!$B$8) | D43: =($A43*Assumptions!$B$8-(ROUND($A43*Assumptions!$B$7,0)*Assumptions!$B$8+D30))/($A43*Assumptions!$B$8) | E43: =($A43*Assumptions!$B$8-(ROUND($A43*Assumptions!$B$7,0)*Assumptions!$B$8+E30))/($A43*Assumptions!$B$8)
A44: 750 | B44: =($A44*Assumptions!$B$8-(ROUND($A44*Assumptions!$B$7,0)*Assumptions!$B$8+B31))/($A44*Assumptions!$B$8) | C44: =($A44*Assumptions!$B$8-(ROUND($A44*Assumptions!$B$7,0)*Assumptions!$B$8+C31))/($A44*Assumptions!$B$8) | D44: =($A44*Assumptions!$B$8-(ROUND($A44*Assumptions!$B$7,0)*Assumptions!$B$8+D31))/($A44*Assumptions!$B$8) | E44: =($A44*Assumptions!$B$8-(ROUND($A44*Assumptions!$B$7,0)*Assumptions!$B$8+E31))/($A44*Assumptions!$B$8)
A45: 1000 | B45: =($A45*Assumptions!$B$8-(ROUND($A45*Assumptions!$B$7,0)*Assumptions!$B$8+B32))/($A45*Assumptions!$B$8) | C45: =($A45*Assumptions!$B$8-(ROUND($A45*Assumptions!$B$7,0)*Assumptions!$B$8+C32))/($A45*Assumptions!$B$8) | D45: =($A45*Assumptions!$B$8-(ROUND($A45*Assumptions!$B$7,0)*Assumptions!$B$8+D32))/($A45*Assumptions!$B$8) | E45: =($A45*Assumptions!$B$8-(ROUND($A45*Assumptions!$B$7,0)*Assumptions!$B$8+E32))/($A45*Assumptions!$B$8)
A48: 3 · Effective cost per screen — the number that explains everything
...
